Workbook

Sheet Lisez-moi
A1: TAIRO — MODÈLE FINANCIER 3 ÉTATS (P&L, trésorerie, bilan)
A3: OBJET
A4: Modélisation financière 3 ans (M1–M36) de la startup Tairo — marketplace de services (Ampio),
A5: location de matériel (Ampindramo) et formation vidéo (Ampianaro) à Madagascar. Devise : Ariary (MGA), hors taxes.
A7: MODÈLE ÉCONOMIQUE
A8: 1. Abonnement prestataire Ampio+ : 24 000 Ar/mois (indexé), souscrit par une part paramétrable des prestataires actifs (10 % par défaut).
A9: 2. Commissions sur prestations, prélevées sur le prestataire : 10 % (Plomberie, Mécanique, Électricité, Jardinage,
A10: Agriculture, Ménage, Irakiraka, Bricolage, BTP, Couture), 15 % (Cuisine), 20 % (Déménagement),
A11: 25 % (Informatique, Transport, Evénementiel, Animaux, Arts, Musiques) — mix paramétrable dans Parametres.
A12: 3. Location entre particuliers : 13 % sur le loueur (caution non commissionnée).
A13: 4. Location professionnelle : paliers sur le total — 30 % (≤ 25 000 Ar), 20 % (25 001–45 000 Ar), 15 % (> 45 000 Ar).
A14: 5. Mise en ligne de vidéos Ampianaro B2B : 64 000 Ar/mois par client professionnel.
... A63: PLANCHER DE CAISSE : lire Financement, bloc « Validation 3 ans » — pic de besoin cumulé avant financement, trésorerie minimale après service de la dette, couverture OK / INSUFFISANT et financement externe minimum indicatif. Leviers : apport (Parametres!B139), mois financés / sécurité (B140, B141), durée de l'emprunt (B144), budget publicité (section 9), salaires (section 13).

Sheet Dashboard
A1: DASHBOARD — Tairo, modèle 3 états (MGA)
A2: Scénario actif : | B2: =Parametres!B3 -> Base
A4: ACTIVITÉ
A5: Chiffre d'affaires Année 1 | B5: ='P&L'!B30 -> 21706621
A6: Chiffre d'affaires Année 2 | B6: ='P&L'!C30 -> 38087024
A7: Chiffre d'affaires Année 3 | B7: ='P&L'!D30 -> 63455216
A8: Croissance CA A2 / A1 | B8: =KPI!C58 -> 0.75462707
A9: Croissance CA A3 / A2 | B9: =KPI!D58 -> 0.66605866
A10: GMV Année 3 | B10: =KPI!D51 -> 77839858
A11: Take rate moyen Année 3 | B11: =KPI!D53 -> 0.14343777
A12: MRR fin Année 3 | B12: =KPI!D54 -> 5294358.1
A13: ARR fin Année 3 | B13: =KPI!D54*12 -> 63532297
A15: RENTABILITÉ
A16: Marge de contribution Année 3 | B16: =IFERROR(SUM(Contribution!Z12:AK12)/SUM(Contribution!Z5:AK5),0) -> 0.8883578
A17: EBITDA Année 3 | B17: ='P&L'!D31 -> 8893982.1
A18: Résultat net Année 1 | B18: ='P&L'!B35 -> -21609440
A19: Résultat net Année 2 | B19: ='P&L'!C35 -> -9978577.1
A20: Résultat net Année 3 | B20: ='P&L'!D35 -> 2560744
A21: Seuil de rentabilité mensuel (CA, moyenne 36 mois) | B21: =-AVERAGE('P&L'!B17:AK17)/AVERAGE('P&L'!B9:AK9) -> 3845081.3
A22: Premier mois EBITDA > 0 | B22: =IFERROR(MATCH(TRUE(),INDEX('P&L'!B18:AK18>0,0),0),"> 36 mois") -> 22
A23: Premier mois de résultat net cumulé positif | B23: =IFERROR(MATCH(TRUE(),INDEX('Base graphique'!B8:AK8>0,0),0),"> 36 mois") -> > 36 mois
A25: UNIT ECONOMICS & OFFRE
A26: CAC offre Année 3 | B26: =KPI!D63 -> 32325.363
A27: CAC demande Année 3 | B27: =KPI!D64 -> 22872.079
A28: LTV / CAC offre fin A3 (cible > 3, LTV bornée 36 mois) | B28: =KPI!D65 -> 5.7660133
A29: LTV / CAC demande fin A3 (cible > 3) | B29: =KPI!D66 -> 15.043695
A30: Prestataires Ampio actifs fin A3 | B30: =KPI!D59 -> 121.62289
A31: Utilisation capacité Ampio fin A3 (alerte si ≥ fill rate max) | B31: =KPI!D60 -> 0.1663472
A32: GMV perdu faute d'offre sur 3 ans | B32: =SUM(KPI!B61:D61) -> 0
A33: Mois d'activation collaborateur 2 (ou > 36) | B33: =IFERROR(MATCH(1,'Plan ventes'!B70:AK70,0),"> 36 mois") -> 25
A35: FINANCEMENT & TRÉSORERIE
A36: Besoin de financement initial (CAPEX + démarrage + sécurité) | B36: =Financement!B11 -> 52008307
A37: Apport en fonds propres | B37: =Financement!B14 -> 9000000
A38: ASK — financement externe recherché | B38: =Financement!B18 -> 43008307
A39: dont equity / quasi-fonds propres (indicatif) | B39: =Financement!B19 -> 12902492
A40: dont dette (indicatif) — modélisé en emprunt | B40: =Financement!B20 -> 30105815
A41: Mensualité de l'emprunt | B41: =Financement!B26 -> 892781.72
A42: Trésorerie fin Année 3 | B42: =Tresorerie!AM25 -> -2445043.6
A43: Trésorerie minimale sur 36 mois | B43: =Financement!B39 -> -2445043.6
A44: Cible : matelas de sécurité | B44: =Financement!B10 -> 8416749
...

Sheet Parametres
A1: TAIRO — HYPOTHÈSES (MGA HT) — MODÈLE 3 ÉTATS
A2: Scénario actif (1 = Prudent, 2 = Base, 3 = Optimiste) | B2: 2
A3: Nom du scénario | B3: =CHOOSE(B2,"Prudent","Base","Optimiste") -> Base
A5: 1 · REVENUS — PRESTATIONS (Tairo Ampio, cœur du modèle — commission prélevée sur le prestataire)
A6: Libellé | B6: Valeur base | C6: Unité | D6: Valeur scénario | E6: Note
A7: Prestations demandées au mois 1 | B7: 75 | C7: prestations/mois | D7: =B7*Scenarios!$E$4 -> 75 | E7: Demande brute. Les prestations réalisées = MIN(demande, capacité de l'offre) — voir section 10.
A8: Panier moyen d'une prestation (année 1) | B8: 35000 | C8: Ar | D8: =B8*Scenarios!$E$6 -> 35000 | E8: Indexé chaque année sur l'inflation des coûts variables (section 6).
A9: Part du GMV — catégories à 10 % (Plomberie, Ménage, BTP…) | B9: 0.7 | C9: % GMV | D9: =B9 -> 0.7
A10: Part du GMV — catégories à 15 % (Cuisine) | B10: 0.1 | C10: % GMV | D10: =B10 -> 0.1
A11: Part du GMV — catégories à 20 % (Déménagement) | B11: 0.05 | C11: % GMV | D11: =B11 -> 0.05
A12: Part du GMV — catégories à 25 % (Informatique, Transport…) | B12: 0.15 | C12: % GMV | D12: =B12 -> 0.15
A13: Take rate moyen services (calculé) | C13: % | D13: =0.1*$D$9+0.15*$D$10+0.2*$D$11+0.25*$D$12 -> 0.1325
A14: Contrôle mix (doit = 100 %) | C14: % | D14: =$D$9+$D$10+$D$11+$D$12 -> 1
A16: 2 · REVENUS — ABONNEMENT Ampio+ (fusionné avec l'offre : part des prestataires actifs abonnés)
A17: Libellé | B17: Valeur base | C17: Unité | D17: Valeur scénario | E17: Note
A18: Prix de l'abonnement mensuel (année 1) | B18: 24000 | C18: Ar/mois | D18: =B18 -> 24000 | E18: Indexé chaque année (section 6).
A19: Part des prestataires actifs abonnés à Ampio+ (pénétration) | B19: 0.1 | C19: % | D19: =B19 -> 0.1 | E19: Remplace l'ancien stock d'abonnés autonome (5 abonnés, churn 6 %) : les abonnés suivent désormais le nombre de prestataires actifs (section 10).
A21: 3 · REVENUS — MISE EN LIGNE VIDÉO (Tairo Ampianaro B2B, clients professionnels)
A22: Libellé | B22: Valeur base | C22: Unité | D22: Valeur scénario | E22: Note
A23: Prix mensuel du service vidéo (année 1) | B23: 64000 | C23: Ar/mois | D23: =B23 -> 64000 | E23: Indexé chaque année (section 6).
A24: Clients vidéo actifs au mois 1 | B24: 15 | C24: clients | D24: =B24*Scenarios!$E$4 -> 15
A25: Churn mensuel clients vidéo | B25: 0.025 | C25: %/mois | D25: =MIN(1,B25*Scenarios!$E$7) -> 0.025
A27: 4 · REVENUS — LOCATION MATÉRIEL PRO (Ampindramo PRO, commission par paliers)
A28: Libellé | B28: Valeur base | C28: Unité | D28: Valeur scénario | E28: Note
A29: Locations pro demandées au mois 1 | B29: 15 | C29: locations/mois | D29: =B29*Scenarios!$E$4 -> 15
A30: Loyer total moyen d'une location pro (année 1) | B30: 15000 | C30: Ar | D30: =B30*Scenarios!$E$6 -> 15000
A31: Part du GMV — total ≤ 25 000 Ar (taux 30 %) | B31: 0.85 | C31: % GMV | D31: =B31 -> 0.85
A32: Part du GMV — 25 001 à 45 000 Ar (taux 20 %) | B32: 0.12 | C32: % GMV | D32: =B32 -> 0.12
A33: Part du GMV — > 45 000 Ar (taux 15 %) | B33: 0.03 | C33: % GMV | D33: =B33 -> 0.03
A34: Take rate moyen location pro (calculé) | C34: % | D34: =0.3*$D$31+0.2*$D$32+0.15*$D$33 -> 0.2835
A35: Contrôle mix (doit = 100 %) | C35: % | D35: =$D$31+$D$32+$D$33 -> 1
A37: 5 · REVENUS — LOCATION MATÉRIEL PARTICULIERS (Ampindramo C2C)
A38: Libellé | B38: Valeur base | C38: Unité | D38: Valeur scénario | E38: Note
A39: Locations particuliers demandées au mois 1 | B39: 12 | C39: locations/mois | D39: =B39*Scenarios!$E$4 -> 12
A40: Loyer total moyen (année 1) | B40: 10000 | C40: Ar | D40: =B40*Scenarios!$E$6 -> 10000
A41: Taux de commission particuliers (fixe, hors caution) | B41: 0.13 | C41: % | D41: =B41 -> 0.13
A43: 6 · INDEXATION DES PRIX & INFLATION (pas annuel, appliqué à chaque nouvelle année du plan)
A44: Libellé | B44: Valeur base | C44: Unité | D44: Valeur scénario | E44: Note
A45: Indexation annuelle des prix (abonnement Ampio+, service vidéo) | B45: 0.08 | C45: %/an | D45: =B45 -> 0.08 | E45: Aligné par défaut sur l'inflation des coûts pour éviter la compression silencieuse des marges.
A46: Inflation annuelle des coûts variables et des paniers / loyers moyens | B46: 0.08 | C46: %/an | D46: =B46 -> 0.08
...

Sheet Scenarios
A1: SCÉNARIOS — multiplicateurs appliqués aux paramètres de base
A2: Le scénario actif se choisit dans Parametres!B2. Colonne « Actif » = multiplicateur appliqué.
A3: Multiplicateur | B3: Prudent (P10) | C3: Base (P50) | D3: Optimiste (P90) | E3: Actif
A4: Volumes de départ (clients, transactions) | B4: 0.7 | C4: 1 | D4: 1.3 | E4: =INDEX(B4:D4,1,Parametres!$B$2) -> 1
A5: Croissance mensuelle | B5: 0.7 | C5: 1 | D5: 1.3 | E5: =INDEX(B5:D5,1,Parametres!$B$2) -> 1
A6: Paniers moyens / prix transactionnels | B6: 0.9 | C6: 1 | D6: 1.1 | E6: =INDEX(B6:D6,1,Parametres!$B$2) -> 1
A7: Churn (attrition) | B7: 1.3 | C7: 1 | D7: 0.8 | E7: =INDEX(B7:D7,1,Parametres!$B$2) -> 1
A8: OPEX (charges fixes) | B8: 1.05 | C8: 1 | D8: 1 | E8: =INDEX(B8:D8,1,Parametres!$B$2) -> 1
A10: Note : pour comparer les scénarios, changer Parametres!B2 (1/2/3) — tout le classeur (Plan ventes, P&L, Trésorerie, KPI, Dashboard) se recalcule automatiquement.

Sheet Plan ventes
A1: PLAN DE VENTES — acquisition, offre (capacité contraignante), demande, GMV, CA (M1–M36) + flag embauche
A2: Année | B2: =INT((B3-1)/12)+1 -> 1 | C2: =INT((C3-1)/12)+1 -> 1 | D2: =INT((D3-1)/12)+1 -> 1 | E2: =INT((E3-1)/12)+1 -> 1 | F2: =INT((F3-1)/12)+1 -> 1 | G2: =INT((G3-1)/12)+1 -> 1 | H2: =INT((H3-1)/12)+1 -> 1 | I2: =INT((I3-1)/12)+1 -> 1 | ... AK2: =INT((AK3-1)/12)+1 -> 3
A3: Mois | B3: 1 | C3: 2 | D3: 3 | E3: 4 | F3: 5 | G3: 6 | H3: 7 | I3: 8 | J3: 9 | K3: 10 | L3: 11 | M3: 12 | N3: 13 | O3: 14 | P3: 15 | Q3: 16 | R3: 17 | S3: 18 | T3: 19 | U3: 20 | V3: 21 | W3: 22 | X3: 23 | Y3: 24 | Z3: 25 | AA3: 26 | AB3: 27 | AC3: 28 | AD3: 29 | AE3: 30 | AF3: 31 | AG3: 32 | AH3: 33 | AI3: 34 | AJ3: 35 | AK3: 36
A5: ACQUISITION → CROISSANCE
A6: Budget publicité / acquisition du mois (Ar, saisi par année — section 9) | B6: =CHOOSE(B$2,Parametres!$D$63,Parametres!$D$64,Parametres!$D$65) -> 400000 | C6: =CHOOSE(C$2,Parametres!$D$63,Parametres!$D$64,Parametres!$D$65) -> 400000 | D6: =CHOOSE(D$2,Parametres!$D$63,Parametres!$D$64,Parametres!$D$65) -> 400000 | E6: =CHOOSE(E$2,Parametres!$D$63,Parametres!$D$64,Parametres!$D$65) -> 400000 | F6: =CHOOSE(F$2,Parametres!$D$63,Parametres!$D$64,Parametres!$D$65) -> 400000 | G6: =CHOOSE(G$2,Parametres!$D$63,Parametres!$D$64,Parametres!$D$65) -> 400000 | H6: =CHOOSE(H$2,Parametres!$D$63,Parametres!$D$64,Parametres!$D$65) -> 400000 | I6: =CHOOSE(I$2,Parametres!$D$63,Parametres!$D$64,Parametres!$D$65) -> 400000 | ... AK6: =CHOOSE(AK$2,Parametres!$D$63,Parametres!$D$64,Parametres!$D$65) -> 600000
A7: Multiplicateur de croissance lié au budget (élasticité, budget du mois précédent, borné) | B7: =1 -> 1 | C7: =MIN(Parametres!$D$69,MAX(Parametres!$D$68,IF(Parametres!$D$66=0,1,(B6/Parametres!$D$66)^Parametres!$D$67))) -> 1 | D7: =MIN(Parametres!$D$69,MAX(Parametres!$D$68,IF(Parametres!$D$66=0,1,(C6/Parametres!$D$66)^Parametres!$D$67))) -> 1 | E7: =MIN(Parametres!$D$69,MAX(Parametres!$D$68,IF(Parametres!$D$66=0,1,(D6/Parametres!$D$66)^Parametres!$D$67))) -> 1 | F7: =MIN(Parametres!$D$69,MAX(Parametres!$D$68,IF(Parametres!$D$66=0,1,(E6/Parametres!$D$66)^Parametres!$D$67))) -> 1 | G7: =MIN(Parametres!$D$69,MAX(Parametres!$D$68,IF(Parametres!$D$66=0,1,(F6/Parametres!$D$66)^Parametres!$D$67))) -> 1 | H7: =MIN(Parametres!$D$69,MAX(Parametres!$D$68,IF(Parametres!$D$66=0,1,(G6/Parametres!$D$66)^Parametres!$D$67))) -> 1 | I7: =MIN(Parametres!$D$69,MAX(Parametres!$D$68,IF(Parametres!$D$66=0,1,(H6/Parametres!$D$66)^Parametres!$D$67))) -> 1 | J7: =MIN(Parametres!$D$69,MAX(Parametres!$D$68,IF(Parametres!$D$66=0,1,(I6/Parametres!$D$66)^Parametres!$D$67))) -> 1 | ... AK7: =MIN(Parametres!$D$69,MAX(Parametres!$D$68,IF(Parametres!$D$66=0,1,(AJ6/Parametres!$D$66)^Parametres!$D$67))) -> 1.2247449
A8: Croissance gelée (stress test : retard de lancement) — 1 = oui | B8: =IF(AND(Parametres!$B$158=1,B$3<=Parametres!$B$160),1,0) -> 0 | C8: =IF(AND(Parametres!$B$158=1,C$3<=Parametres!$B$160),1,0) -> 0 | D8: =IF(AND(Parametres!$B$158=1,D$3<=Parametres!$B$160),1,0) -> 0 | E8: =IF(AND(Parametres!$B$158=1,E$3<=Parametres!$B$160),1,0) -> 0 | F8: =IF(AND(Parametres!$B$158=1,F$3<=Parametres!$B$160),1,0) -> 0 | G8: =IF(AND(Parametres!$B$158=1,G$3<=Parametres!$B$160),1,0) -> 0 | H8: =IF(AND(Parametres!$B$158=1,H$3<=Parametres!$B$160),1,0) -> 0 | I8: =IF(AND(Parametres!$B$158=1,I$3<=Parametres!$B$160),1,0) -> 0 | ... AK8: =IF(AND(Parametres!$B$158=1,AK$3<=Parametres!$B$160),1,0) -> 0
A10: OFFRE & DEMANDE — PRESTATIONS AMPIO (prestataires, capacité, GMV, commissions, abonnements Ampio+)
A11: Nouveaux prestataires onboardés (M1 = stock initial) | B11: =Parametres!$D$81*(1-IF(Parametres!$B$158=1,Parametres!$B$159,0)) -> 25 | C11: =IF(B70=1,Parametres!$D$83,Parametres!$D$82) -> 3 | D11: =IF(C70=1,Parametres!$D$83,Parametres!$D$82) -> 3 | E11: =IF(D70=1,Parametres!$D$83,Parametres!$D$82) -> 3 | F11: =IF(E70=1,Parametres!$D$83,Parametres!$D$82) -> 3 | G11: =IF(F70=1,Parametres!$D$83,Parametres!$D$82) -> 3 | H11: =IF(G70=1,Parametres!$D$83,Parametres!$D$82) -> 3 | I11: =IF(H70=1,Parametres!$D$83,Parametres!$D$82) -> 3 | J11: =IF(I70=1,Parametres!$D$83,Parametres!$D$82) -> 3 | ... AK11: =IF(AJ70=1,Parametres!$D$83,Parametres!$D$82) -> 8
A12: Prestataires perdus (churn) | B12: =0 -> 0 | C12: =B13*Parametres!$D$84 -> 0.75 | D12: =C13*Parametres!$D$84 -> 0.8175 | E12: =D13*Parametres!$D$84 -> 0.882975 | F12: =E13*Parametres!$D$84 -> 0.94648575 | G12: =F13*Parametres!$D$84 -> 1.0080912 | H12: =G13*Parametres!$D$84 -> 1.0678484 | I12: =H13*Parametres!$D$84 -> 1.125813 | J12: =I13*Parametres!$D$84 -> 1.1820386 | ... AK12: =AJ13*Parametres!$D$84 -> 3.5141098
A13: Prestataires actifs (stock × (1 − churn) + nouveaux) | B13: =B11 -> 25 | C13: =B13*(1-Parametres!$D$84)+C11 -> 27.25 | D13: =C13*(1-Parametres!$D$84)+D11 -> 29.4325 | E13: =D13*(1-Parametres!$D$84)+E11 -> 31.549525 | F13: =E13*(1-Parametres!$D$84)+F11 -> 33.603039 | G13: =F13*(1-Parametres!$D$84)+G11 -> 35.594948 | H13: =G13*(1-Parametres!$D$84)+H11 -> 37.5271 | I13: =H13*(1-Parametres!$D$84)+I11 -> 39.401287 | J13: =I13*(1-Parametres!$D$84)+J11 -> 41.219248 | ... AK13: =AJ13*(1-Parametres!$D$84)+AK11 -> 121.62289
A14: Capacité mensuelle (actifs × max par mois × fill rate max) | B14: =B13*Parametres!$D$85*Parametres!$D$95 -> 160 | C14: =C13*Parametres!$D$85*Parametres!$D$95 -> 174.4 | D14: =D13*Parametres!$D$85*Parametres!$D$95 -> 188.368 | E14: =E13*Parametres!$D$85*Parametres!$D$95 -> 201.91696 | F14: =F13*Parametres!$D$85*Parametres!$D$95 -> 215.05945 | G14: =G13*Parametres!$D$85*Parametres!$D$95 -> 227.80767 | H14: =H13*Parametres!$D$85*Parametres!$D$95 -> 240.17344 | I14: =I13*Parametres!$D$85*Parametres!$D$95 -> 252.16823 | ... AK14: =AK13*Parametres!$D$85*Parametres!$D$95 -> 778.38646
A15: Abonnés Ampio+ (pénétration × prestataires actifs) | B15: =B13*Parametres!$D$19 -> 2.5 | C15: =C13*Parametres!$D$19 -> 2.725 | D15: =D13*Parametres!$D$19 -> 2.94325 | E15: =E13*Parametres!$D$19 -> 3.1549525 | F15: =F13*Parametres!$D$19 -> 3.3603039 | G15: =G13*Parametres!$D$19 -> 3.5594948 | H15: =H13*Parametres!$D$19 -> 3.75271 | I15: =I13*Parametres!$D$19 -> 3.9401287 | ... AK15: =AK13*Parametres!$D$19 -> 12.162289
A16: Prix de l'abonnement indexé | B16: =Parametres!$D$18*(1+Parametres!$D$45)^(B$2-1) -> 24000 | C16: =Parametres!$D$18*(1+Parametres!$D$45)^(C$2-1) -> 24000 | D16: =Parametres!$D$18*(1+Parametres!$D$45)^(D$2-1) -> 24000 | E16: =Parametres!$D$18*(1+Parametres!$D$45)^(E$2-1) -> 24000 | F16: =Parametres!$D$18*(1+Parametres!$D$45)^(F$2-1) -> 24000 | G16: =Parametres!$D$18*(1+Parametres!$D$45)^(G$2-1) -> 24000 | H16: =Parametres!$D$18*(1+Parametres!$D$45)^(H$2-1) -> 24000 | I16: =Parametres!$D$18*(1+Parametres!$D$45)^(I$2-1) -> 24000 | ... AK16: =Parametres!$D$18*(1+Parametres!$D$45)^(AK$2-1) -> 27993.6
A17: CA abonnements Ampio+ (MRR) | B17: =B15*B16 -> 60000 | C17: =C15*C16 -> 65400 | D17: =D15*D16 -> 70638 | E17: =E15*E16 -> 75718.86 | F17: =F15*F16 -> 80647.294 | G17: =G15*G16 -> 85427.875 | H17: =H15*H16 -> 90065.039 | I17: =I15*I16 -> 94563.088 | ... AK17: =AK15*AK16 -> 340466.24
A18: Demande (prestations) — croissance section 7 × multiplicateur acquisition | B18: =Parametres!$D$7*(1-IF(Parametres!$B$158=1,Parametres!$B$159,0)) -> 75 | C18: =B18*(1+IF(C8=1,0,IF(AND(C$2>=2,B70=0),Parametres!$D$58,CHOOSE(C$2,Parametres!$F$52,Parametres!$G$52,Parametres!$H$52))*C7)) -> 76.5 | D18: =C18*(1+IF(D8=1,0,IF(AND(D$2>=2,C70=0),Parametres!$D$58,CHOOSE(D$2,Parametres!$F$52,Parametres!$G$52,Parametres!$H$52))*D7)) -> 78.03 | E18: =D18*(1+IF(E8=1,0,IF(AND(E$2>=2,D70=0),Parametres!$D$58,CHOOSE(E$2,Parametres!$F$52,Parametres!$G$52,Parametres!$H$52))*E7)) -> 79.5906 | F18: =E18*(1+IF(F8=1,0,IF(AND(F$2>=2,E70=0),Parametres!$D$58,CHOOSE(F$2,Parametres!$F$52,Parametres!$G$52,Parametres!$H$52))*F7)) -> 81.182412 | G18: =F18*(1+IF(G8=1,0,IF(AND(G$2>=2,F70=0),Parametres!$D$58,CHOOSE(G$2,Parametres!$F$52,Parametres!$G$52,Parametres!$H$52))*G7)) -> 82.80606 | H18: =G18*(1+IF(H8=1,0,IF(AND(H$2>=2,G70=0),Parametres!$D$58,CHOOSE(H$2,Parametres!$F$52,Parametres!$G$52,Parametres!$H$52))*H7)) -> 84.462181 | I18: =H18*(1+IF(I8=1,0,IF(AND(I$2>=2,H70=0),Parametres!$D$58,CHOOSE(I$2,Parametres!$F$52,Parametres!$G$52,Parametres!$H$52))*I7)) -> 86.151425 | J18: =I18*(1+IF(J8=1,0,IF(AND(J$2>=2,I70=0),Parametres!$D$58,CHOOSE(J$2,Parametres!$F$52,Parametres!$G$52,Parametres!$H$52))*J7)) -> 87.874454 | ... AK18: =AJ18*(1+IF(AK8=1,0,IF(AND(AK$2>=2,AJ70=0),Parametres!$D$58,CHOOSE(AK$2,Parametres!$F$52,Parametres!$G$52,Parametres!$H$52))*AK7)) -> 161.85301
A19: Prestations réalisées = MIN(demande, capacité) | B19: =MIN(B18,B14) -> 75 | C19: =MIN(C18,C14) -> 76.5 | D19: =MIN(D18,D14) -> 78.03 | E19: =MIN(E18,E14) -> 79.5906 | F19: =MIN(F18,F14) -> 81.182412 | G19: =MIN(G18,G14) -> 82.80606 | H19: =MIN(H18,H14) -> 84.462181 | I19: =MIN(I18,I14) -> 86.151425 | ... AK19: =MIN(AK18,AK14) -> 161.85301
A20: Demande non servie (pénurie d'offre) | B20: =B18-B19 -> 0 | C20: =C18-C19 -> 0 | D20: =D18-D19 -> 0 | E20: =E18-E19 -> 0 | F20: =F18-F19 -> 0 | G20: =G18-G19 -> 0 | H20: =H18-H19 -> 0 | I20: =I18-I19 -> 0 | ... AK20: =AK18-AK19 -> 0
A21: Taux d'utilisation de la capacité brute (réalisées / (actifs × max)) | B21: =IF(B13*Parametres!$D$85=0,0,B19/(B13*Parametres!$D$85)) -> 0.375 | C21: =IF(C13*Parametres!$D$85=0,0,C19/(C13*Parametres!$D$85)) -> 0.35091743 | D21: =IF(D13*Parametres!$D$85=0,0,D19/(D13*Parametres!$D$85)) -> 0.33139387 | E21: =IF(E13*Parametres!$D$85=0,0,E19/(E13*Parametres!$D$85)) -> 0.31533993 | F21: =IF(F13*Parametres!$D$85=0,0,F19/(F13*Parametres!$D$85)) -> 0.30199059 | G21: =IF(G13*Parametres!$D$85=0,0,G19/(G13*Parametres!$D$85)) -> 0.29079288 | H21: =IF(H13*Parametres!$D$85=0,0,H19/(H13*Parametres!$D$85)) -> 0.28133729 | I21: =IF(I13*Parametres!$D$85=0,0,I19/(I13*Parametres!$D$85)) -> 0.27331412 | ... AK21: =IF(AK13*Parametres!$D$85=0,0,AK19/(AK13*Parametres!$D$85)) -> 0.1663472
A22: Panier / loyer moyen (indexé par an) | B22: =Parametres!$D$8*(1+Parametres!$D$46)^(B$2-1) -> 35000 | C22: =Parametres!$D$8*(1+Parametres!$D$46)^(C$2-1) -> 35000 | D22: =Parametres!$D$8*(1+Parametres!$D$46)^(D$2-1) -> 35000 | E22: =Parametres!$D$8*(1+Parametres!$D$46)^(E$2-1) -> 35000 | F22: =Parametres!$D$8*(1+Parametres!$D$46)^(F$2-1) -> 35000 | G22: =Parametres!$D$8*(1+Parametres!$D$46)^(G$2-1) -> 35000 | H22: =Parametres!$D$8*(1+Parametres!$D$46)^(H$2-1) -> 35000 | I22: =Parametres!$D$8*(1+Parametres!$D$46)^(I$2-1) -> 35000 | ... AK22: =Parametres!$D$8*(1+Parametres!$D$46)^(AK$2-1) -> 40824
A23: GMV prestations | B23: =B19*B22 -> 2625000 | C23: =C19*C22 -> 2677500 | D23: =D19*D22 -> 2731050 | E23: =E19*E22 -> 2785671 | F23: =F19*F22 -> 2841384.4 | G23: =G19*G22 -> 2898212.1 | H23: =H19*H22 -> 2956176.4 | I23: =I19*I22 -> 3015299.9 | ... AK23: =AK19*AK22 -> 6607487.2
A24: CA commissions prestations (take rate mix − subvention de lancement M1–M6) | B24: =MAX(0,B23*(Parametres!$D$13-IF(B$3<=Parametres!$D$99,Parametres!$D$100,0))) -> 295312.5 | C24: =MAX(0,C23*(Parametres!$D$13-IF(C$3<=Parametres!$D$99,Parametres!$D$100,0))) -> 301218.75 | D24: =MAX(0,D23*(Parametres!$D$13-IF(D$3<=Parametres!$D$99,Parametres!$D$100,0))) -> 307243.12 | E24: =MAX(0,E23*(Parametres!$D$13-IF(E$3<=Parametres!$D$99,Parametres!$D$100,0))) -> 313387.99 | F24: =MAX(0,F23*(Parametres!$D$13-IF(F$3<=Parametres!$D$99,Parametres!$D$100,0))) -> 319655.75 | G24: =MAX(0,G23*(Parametres!$D$13-IF(G$3<=Parametres!$D$99,Parametres!$D$100,0))) -> 326048.86 | H24: =MAX(0,H23*(Parametres!$D$13-IF(H$3<=Parametres!$D$99,Parametres!$D$100,0))) -> 391693.37 | I24: =MAX(0,I23*(Parametres!$D$13-IF(I$3<=Parametres!$D$99,Parametres!$D$100,0))) -> 399527.23 | ... AK24: =MAX(0,AK23*(Parametres!$D$13-IF(AK$3<=Parametres!$D$99,Parametres!$D$100,0))) -> 875492.06
A26: MISE EN LIGNE VIDÉO — Ampianaro B2B (croissance ralentie A2/A3 × multiplicateur acquisition)
A27: Nouveaux clients vidéo (croissance nette + remplacement du churn) | B27: =B29 -> 15 | C27: =C29-B29*(1-Parametres!$D$25) -> 1.125 | D27: =D29-C29*(1-Parametres!$D$25) -> 1.18125 | E27: =E29-D29*(1-Parametres!$D$25) -> 1.2403125 | F27: =F29-E29*(1-Parametres!$D$25) -> 1.3023281 | G27: =G29-F29*(1-Parametres!$D$25) -> 1.3674445 | H27: =H29-G29*(1-Parametres!$D$25) -> 1.4358168 | I27: =I29-H29*(1-Parametres!$D$25) -> 1.5076076 | J27: =J29-I29*(1-Parametres!$D$25) -> 1.582988 | ... AK27: =AK29-AJ29*(1-Parametres!$D$25) -> 3.952131
A28: Clients perdus (churn) | B28: =0 -> 0 | C28: =B29*Parametres!$D$25 -> 0.375 | D28: =C29*Parametres!$D$25 -> 0.39375 | E28: =D29*Parametres!$D$25 -> 0.4134375 | F28: =E29*Parametres!$D$25 -> 0.43410938 | G28: =F29*Parametres!$D$25 -> 0.45581484 | H28: =G29*Parametres!$D$25 -> 0.47860559 | I28: =H29*Parametres!$D$25 -> 0.50253587 | J28: =I29*Parametres!$D$25 -> 0.52766266 | ... AK28: =AJ29*Parametres!$D$25 -> 1.6002514
A29: Clients vidéo actifs | B29: =Parametres!$D$24*(1-IF(Parametres!$B$158=1,Parametres!$B$159,0)) -> 15 | C29: =B29*(1+IF(C8=1,0,CHOOSE(C$2,Parametres!$F$51,Parametres!$G$51,Parametres!$H$51)*C7)) -> 15.75 | D29: =C29*(1+IF(D8=1,0,CHOOSE(D$2,Parametres!$F$51,Parametres!$G$51,Parametres!$H$51)*D7)) -> 16.5375 | E29: =D29*(1+IF(E8=1,0,CHOOSE(E$2,Parametres!$F$51,Parametres!$G$51,Parametres!$H$51)*E7)) -> 17.364375 | F29: =E29*(1+IF(F8=1,0,CHOOSE(F$2,Parametres!$F$51,Parametres!$G$51,Parametres!$H$51)*F7)) -> 18.232594 | G29: =F29*(1+IF(G8=1,0,CHOOSE(G$2,Parametres!$F$51,Parametres!$G$51,Parametres!$H$51)*G7)) -> 19.144223 | H29: =G29*(1+IF(H8=1,0,CHOOSE(H$2,Parametres!$F$51,Parametres!$G$51,Parametres!$H$51)*H7)) -> 20.101435 | I29: =H29*(1+IF(I8=1,0,CHOOSE(I$2,Parametres!$F$51,Parametres!$G$51,Parametres!$H$51)*I7)) -> 21.106506 | J29: =I29*(1+IF(J8=1,0,CHOOSE(J$2,Parametres!$F$51,Parametres!$G$51,Parametres!$H$51)*J7)) -> 22.161832 | ... AK29: =AJ29*(1+IF(AK8=1,0,CHOOSE(AK$2,Parametres!$F$51,Parametres!$G$51,Parametres!$H$51)*AK7)) -> 66.361934
A30: Prix du service vidéo indexé | B30: =Parametres!$D$23*(1+Parametres!$D$45)^(B$2-1) -> 64000 | C30: =Parametres!$D$23*(1+Parametres!$D$45)^(C$2-1) -> 64000 | D30: =Parametres!$D$23*(1+Parametres!$D$45)^(D$2-1) -> 64000 | E30: =Parametres!$D$23*(1+Parametres!$D$45)^(E$2-1) -> 64000 | F30: =Parametres!$D$23*(1+Parametres!$D$45)^(F$2-1) -> 64000 | G30: =Parametres!$D$23*(1+Parametres!$D$45)^(G$2-1) -> 64000 | H30: =Parametres!$D$23*(1+Parametres!$D$45)^(H$2-1) -> 64000 | I30: =Parametres!$D$23*(1+Parametres!$D$45)^(I$2-1) -> 64000 | ... AK30: =Parametres!$D$23*(1+Parametres!$D$45)^(AK$2-1) -> 74649.6
A31: CA vidéo (MRR Ampianaro B2B) | B31: =B29*B30 -> 960000 | C31: =C29*C30 -> 1008000 | D31: =D29*D30 -> 1058400 | E31: =E29*E30 -> 1111320 | F31: =F29*F30 -> 1166886 | G31: =G29*G30 -> 1225230.3 | H31: =H29*H30 -> 1286491.8 | I31: =I29*I30 -> 1350816.4 | ... AK31: =AK29*AK30 -> 4953891.9
A33: OFFRE & DEMANDE — LOCATIONS PRO Ampindramo B2B2C (loueurs, capacité, paliers 30/20/15 %)
A34: Nouveaux loueurs pro onboardés (M1 = stock initial) | B34: =Parametres!$D$86*(1-IF(Parametres!$B$158=1,Parametres!$B$159,0)) -> 8 | C34: =IF(B70=1,Parametres!$D$88,Parametres!$D$87) -> 1 | D34: =IF(C70=1,Parametres!$D$88,Parametres!$D$87) -> 1 | E34: =IF(D70=1,Parametres!$D$88,Parametres!$D$87) -> 1 | F34: =IF(E70=1,Parametres!$D$88,Parametres!$D$87) -> 1 | G34: =IF(F70=1,Parametres!$D$88,Parametres!$D$87) -> 1 | H34: =IF(G70=1,Parametres!$D$88,Parametres!$D$87) -> 1 | I34: =IF(H70=1,Parametres!$D$88,Parametres!$D$87) -> 1 | J34: =IF(I70=1,Parametres!$D$88,Parametres!$D$87) -> 1 | ... AK34: =IF(AJ70=1,Parametres!$D$88,Parametres!$D$87) -> 2
A35: Loueurs pro perdus (churn) | B35: =0 -> 0 | C35: =B36*Parametres!$D$89 -> 0.16 | D35: =C36*Parametres!$D$89 -> 0.1768 | E35: =D36*Parametres!$D$89 -> 0.193264 | F35: =E36*Parametres!$D$89 -> 0.20939872 | G35: =F36*Parametres!$D$89 -> 0.22521075 | H35: =G36*Parametres!$D$89 -> 0.24070653 | I35: =H36*Parametres!$D$89 -> 0.2558924 | J35: =I36*Parametres!$D$89 -> 0.27077455 | ... AK35: =AJ36*Parametres!$D$89 -> 0.7602918
A36: Loueurs pro actifs (stock × (1 − churn) + nouveaux) | B36: =B34 -> 8 | C36: =B36*(1-Parametres!$D$89)+C34 -> 8.84 | D36: =C36*(1-Parametres!$D$89)+D34 -> 9.6632 | E36: =D36*(1-Parametres!$D$89)+E34 -> 10.469936 | F36: =E36*(1-Parametres!$D$89)+F34 -> 11.260537 | G36: =F36*(1-Parametres!$D$89)+G34 -> 12.035327 | H36: =G36*(1-Parametres!$D$89)+H34 -> 12.79462 | I36: =H36*(1-Parametres!$D$89)+I34 -> 13.538728 | J36: =I36*(1-Parametres!$D$89)+J34 -> 14.267953 | ... AK36: =AJ36*(1-Parametres!$D$89)+AK34 -> 39.254298
A37: Capacité mensuelle (actifs × max par mois × fill rate max) | B37: =B36*Parametres!$D$90*Parametres!$D$95 -> 25.6 | C37: =C36*Parametres!$D$90*Parametres!$D$95 -> 28.288 | D37: =D36*Parametres!$D$90*Parametres!$D$95 -> 30.92224 | E37: =E36*Parametres!$D$90*Parametres!$D$95 -> 33.503795 | F37: =F36*Parametres!$D$90*Parametres!$D$95 -> 36.033719 | G37: =G36*Parametres!$D$90*Parametres!$D$95 -> 38.513045 | H37: =H36*Parametres!$D$90*Parametres!$D$95 -> 40.942784 | I37: =I36*Parametres!$D$90*Parametres!$D$95 -> 43.323928 | ... AK37: =AK36*Parametres!$D$90*Parametres!$D$95 -> 125.61375
A38: Demande (locations pro) — croissance section 7 × multiplicateur acquisition | B38: =Parametres!$D$29*(1-IF(Parametres!$B$158=1,Parametres!$B$159,0)) -> 15 | C38: =B38*(1+IF(C8=1,0,IF(AND(C$2>=2,B70=0),Parametres!$D$59,CHOOSE(C$2,Parametres!$F$53,Parametres!$G$53,Parametres!$H$53))*C7)) -> 15.27 | D38: =C38*(1+IF(D8=1,0,IF(AND(D$2>=2,C70=0),Parametres!$D$59,CHOOSE(D$2,Parametres!$F$53,Parametres!$G$53,Parametres!$H$53))*D7)) -> 15.54486 | E38: =D38*(1+IF(E8=1,0,IF(AND(E$2>=2,D70=0),Parametres!$D$59,CHOOSE(E$2,Parametres!$F$53,Parametres!$G$53,Parametres!$H$53))*E7)) -> 15.824667 | F38: =E38*(1+IF(F8=1,0,IF(AND(F$2>=2,E70=0),Parametres!$D$59,CHOOSE(F$2,Parametres!$F$53,Parametres!$G$53,Parametres!$H$53))*F7)) -> 16.109511 | G38: =F38*(1+IF(G8=1,0,IF(AND(G$2>=2,F70=0),Parametres!$D$59,CHOOSE(G$2,Parametres!$F$53,Parametres!$G$53,Parametres!$H$53))*G7)) -> 16.399483 | H38: =G38*(1+IF(H8=1,0,IF(AND(H$2>=2,G70=0),Parametres!$D$59,CHOOSE(H$2,Parametres!$F$53,Parametres!$G$53,Parametres!$H$53))*H7)) -> 16.694673 | I38: =H38*(1+IF(I8=1,0,IF(AND(I$2>=2,H70=0),Parametres!$D$59,CHOOSE(I$2,Parametres!$F$53,Parametres!$G$53,Parametres!$H$53))*I7)) -> 16.995178 | J38: =I38*(1+IF(J8=1,0,IF(AND(J$2>=2,I70=0),Parametres!$D$59,CHOOSE(J$2,Parametres!$F$53,Parametres!$G$53,Parametres!$H$53))*J7)) -> 17.301091 | ... AK38: =AJ38*(1+IF(AK8=1,0,IF(AND(AK$2>=2,AJ70=0),Parametres!$D$59,CHOOSE(AK$2,Parametres!$F$53,Parametres!$G$53,Parametres!$H$53))*AK7)) -> 30.79719
A39: Locations pro réalisées = MIN(demande, capacité) | B39: =MIN(B38,B37) -> 15 | C39: =MIN(C38,C37) -> 15.27 | D39: =MIN(D38,D37) -> 15.54486 | E39: =MIN(E38,E37) -> 15.824667 | F39: =MIN(F38,F37) -> 16.109511 | G39: =MIN(G38,G37) -> 16.399483 | H39: =MIN(H38,H37) -> 16.694673 | I39: =MIN(I38,I37) -> 16.995178 | ... AK39: =MIN(AK38,AK37) -> 30.79719
A40: Demande non servie (pénurie d'offre) | B40: =B38-B39 -> 0 | C40: =C38-C39 -> 0 | D40: =D38-D39 -> 0 | E40: =E38-E39 -> 0 | F40: =F38-F39 -> 0 | G40: =G38-G39 -> 0 | H40: =H38-H39 -> 0 | I40: =I38-I39 -> 0 | ... AK40: =AK38-AK39 -> 0
A41: Taux d'utilisation de la capacité brute (réalisées / (actifs × max)) | B41: =IF(B36*Parametres!$D$90=0,0,B39/(B36*Parametres!$D$90)) -> 0.46875 | C41: =IF(C36*Parametres!$D$90=0,0,C39/(C36*Parametres!$D$90)) -> 0.43184389 | D41: =IF(D36*Parametres!$D$90=0,0,D39/(D36*Parametres!$D$90)) -> 0.40216647 | E41: =IF(E36*Parametres!$D$90=0,0,E39/(E36*Parametres!$D$90)) -> 0.3778597 | F41: =IF(F36*Parametres!$D$90=0,0,F39/(F36*Parametres!$D$90)) -> 0.35765415 | G41: =IF(G36*Parametres!$D$90=0,0,G39/(G36*Parametres!$D$90)) -> 0.34065305 | H41: =IF(H36*Parametres!$D$90=0,0,H39/(H36*Parametres!$D$90)) -> 0.32620495 | I41: =IF(I36*Parametres!$D$90=0,0,I39/(I36*Parametres!$D$90)) -> 0.31382524 | ... AK41: =IF(AK36*Parametres!$D$90=0,0,AK39/(AK36*Parametres!$D$90)) -> 0.19613897
A42: Panier / loyer moyen (indexé par an) | B42: =Parametres!$D$30*(1+Parametres!$D$46)^(B$2-1) -> 15000 | C42: =Parametres!$D$30*(1+Parametres!$D$46)^(C$2-1) -> 15000 | D42: =Parametres!$D$30*(1+Parametres!$D$46)^(D$2-1) -> 15000 | E42: =Parametres!$D$30*(1+Parametres!$D$46)^(E$2-1) -> 15000 | F42: =Parametres!$D$30*(1+Parametres!$D$46)^(F$2-1) -> 15000 | G42: =Parametres!$D$30*(1+Parametres!$D$46)^(G$2-1) -> 15000 | H42: =Parametres!$D$30*(1+Parametres!$D$46)^(H$2-1) -> 15000 | I42: =Parametres!$D$30*(1+Parametres!$D$46)^(I$2-1) -> 15000 | ... AK42: =Parametres!$D$30*(1+Parametres!$D$46)^(AK$2-1) -> 17496
A43: GMV locations pro | B43: =B39*B42 -> 225000 | C43: =C39*C42 -> 229050 | D43: =D39*D42 -> 233172.9 | E43: =E39*E42 -> 237370.01 | F43: =F39*F42 -> 241642.67 | G43: =G39*G42 -> 245992.24 | H43: =H39*H42 -> 250420.1 | I43: =I39*I42 -> 254927.66 | ... AK43: =AK39*AK42 -> 538827.64
A44: CA commissions locations pro | B44: =B43*Parametres!$D$34 -> 63787.5 | C44: =C43*Parametres!$D$34 -> 64935.675 | D44: =D43*Parametres!$D$34 -> 66104.517 | E44: =E43*Parametres!$D$34 -> 67294.398 | F44: =F43*Parametres!$D$34 -> 68505.698 | G44: =G43*Parametres!$D$34 -> 69738.8 | H44: =H43*Parametres!$D$34 -> 70994.099 | I44: =I43*Parametres!$D$34 -> 72271.992 | ... AK44: =AK43*Parametres!$D$34 -> 152757.64
...

Sheet Contribution
A1: CASCADE DE CONTRIBUTION — coûts variables suivant le volume (MGA)
A2: Année | B2: ='P&L'!B2 -> 1 | C2: ='P&L'!C2 -> 1 | D2: ='P&L'!D2 -> 1 | E2: ='P&L'!E2 -> 1 | F2: ='P&L'!F2 -> 1 | G2: ='P&L'!G2 -> 1 | H2: ='P&L'!H2 -> 1 | I2: ='P&L'!I2 -> 1 | ... AK2: ='P&L'!AK2 -> 3
A3: Mois | B3: ='P&L'!B3 -> 1 | C3: ='P&L'!C3 -> 2 | D3: ='P&L'!D3 -> 3 | E3: ='P&L'!E3 -> 4 | F3: ='P&L'!F3 -> 5 | G3: ='P&L'!G3 -> 6 | H3: ='P&L'!H3 -> 7 | I3: ='P&L'!I3 -> 8 | ... AK3: ='P&L'!AK3 -> 36
A5: Chiffre d'affaires (IFRS 15) | B5: ='P&L'!B5 -> 1394700 | C5: ='P&L'!C5 -> 1455388.4 | D5: ='P&L'!D5 -> 1518457.2 | E5: ='P&L'!E5 -> 1584033.8 | F5: ='P&L'!F5 -> 1652252 | G5: ='P&L'!G5 -> 1723251.5 | H5: ='P&L'!H5 -> 1856302 | I5: ='P&L'!I5 -> 1934492.3 | ... AK5: ='P&L'!AK5 -> 6351643.2
A6: dont MM 3 % (abo Ampio+ + GMV, hors vidéo) | B6: =-('Plan ventes'!B17+'Plan ventes'!B23+'Plan ventes'!B43+'Plan ventes'!B56)*Parametres!$D$105 -> -90900 | C6: =-('Plan ventes'!C17+'Plan ventes'!C23+'Plan ventes'!C43+'Plan ventes'!C56)*Parametres!$D$105 -> -92812.5 | D6: =-('Plan ventes'!D17+'Plan ventes'!D23+'Plan ventes'!D43+'Plan ventes'!D56)*Parametres!$D$105 -> -94754.637 | E6: =-('Plan ventes'!E17+'Plan ventes'!E23+'Plan ventes'!E43+'Plan ventes'!E56)*Parametres!$D$105 -> -96727.238 | F6: =-('Plan ventes'!F17+'Plan ventes'!F23+'Plan ventes'!F43+'Plan ventes'!F56)*Parametres!$D$105 -> -98731.14 | G6: =-('Plan ventes'!G17+'Plan ventes'!G23+'Plan ventes'!G43+'Plan ventes'!G56)*Parametres!$D$105 -> -100767.19 | H6: =-('Plan ventes'!H17+'Plan ventes'!H23+'Plan ventes'!H43+'Plan ventes'!H56)*Parametres!$D$105 -> -102836.24 | I6: =-('Plan ventes'!I17+'Plan ventes'!I23+'Plan ventes'!I43+'Plan ventes'!I56)*Parametres!$D$105 -> -104939.16 | ... AK6: =-('Plan ventes'!AK17+'Plan ventes'!AK23+'Plan ventes'!AK43+'Plan ventes'!AK56)*Parametres!$D$105 -> -231303.92
A7: dont SMS (Ampio + C2C) | B7: =-('Plan ventes'!B19+'Plan ventes'!B52)*Parametres!$D$104*(1+Parametres!$D$46)^(B$2-1) -> -6213.54 | C7: =-('Plan ventes'!C19+'Plan ventes'!C52)*Parametres!$D$104*(1+Parametres!$D$46)^(C$2-1) -> -6333.5256 | D7: =-('Plan ventes'!D19+'Plan ventes'!D52)*Parametres!$D$104*(1+Parametres!$D$46)^(D$2-1) -> -6455.8466 | E7: =-('Plan ventes'!E19+'Plan ventes'!E52)*Parametres!$D$104*(1+Parametres!$D$46)^(E$2-1) -> -6580.5488 | F7: =-('Plan ventes'!F19+'Plan ventes'!F52)*Parametres!$D$104*(1+Parametres!$D$46)^(F$2-1) -> -6707.6789 | G7: =-('Plan ventes'!G19+'Plan ventes'!G52)*Parametres!$D$104*(1+Parametres!$D$46)^(G$2-1) -> -6837.2843 | H7: =-('Plan ventes'!H19+'Plan ventes'!H52)*Parametres!$D$104*(1+Parametres!$D$46)^(H$2-1) -> -6969.4136 | I7: =-('Plan ventes'!I19+'Plan ventes'!I52)*Parametres!$D$104*(1+Parametres!$D$46)^(I$2-1) -> -7104.1163 | ... AK7: =-('Plan ventes'!AK19+'Plan ventes'!AK52)*Parametres!$D$104*(1+Parametres!$D$46)^(AK$2-1) -> -15078.213
A8: dont support / modération (Ar / transaction) | B8: =-'Plan ventes'!B64*Parametres!$D$106 -> -102000 | C8: =-'Plan ventes'!C64*Parametres!$D$106 -> -103950 | D8: =-'Plan ventes'!D64*Parametres!$D$106 -> -105937.56 | E8: =-'Plan ventes'!E64*Parametres!$D$106 -> -107963.41 | F8: =-'Plan ventes'!F64*Parametres!$D$106 -> -110028.29 | G8: =-'Plan ventes'!G64*Parametres!$D$106 -> -112132.95 | H8: =-'Plan ventes'!H64*Parametres!$D$106 -> -114278.17 | I8: =-'Plan ventes'!I64*Parametres!$D$106 -> -116464.74 | ... AK8: =-'Plan ventes'!AK64*Parametres!$D$106 -> -211798.83
A9: dont vérification nouveaux clients (prestataires, loueurs, vidéo, demande) | B9: =-'Plan ventes'!B66*Parametres!$D$107 -> -189900 | C9: =-'Plan ventes'!C66*Parametres!$D$107 -> -62152.5 | D9: =-'Plan ventes'!D66*Parametres!$D$107 -> -63215.652 | E9: =-'Plan ventes'!E66*Parametres!$D$107 -> -64304.471 | F9: =-'Plan ventes'!F66*Parametres!$D$107 -> -65419.713 | G9: =-'Plan ventes'!G66*Parametres!$D$107 -> -66562.162 | H9: =-'Plan ventes'!H66*Parametres!$D$107 -> -67732.629 | I9: =-'Plan ventes'!I66*Parametres!$D$107 -> -68931.956 | ... AK9: =-'Plan ventes'!AK66*Parametres!$D$107 -> -137165.87
A10: dont provision litiges (% GMV) | B10: =-'Plan ventes'!B60*Parametres!$D$108 -> -29700 | C10: =-'Plan ventes'!C60*Parametres!$D$108 -> -30283.5 | D10: =-'Plan ventes'!D60*Parametres!$D$108 -> -30878.499 | E10: =-'Plan ventes'!E60*Parametres!$D$108 -> -31485.224 | F10: =-'Plan ventes'!F60*Parametres!$D$108 -> -32103.907 | G10: =-'Plan ventes'!G60*Parametres!$D$108 -> -32734.784 | H10: =-'Plan ventes'!H60*Parametres!$D$108 -> -33378.096 | I10: =-'Plan ventes'!I60*Parametres!$D$108 -> -34034.089 | ... AK10: =-'Plan ventes'!AK60*Parametres!$D$108 -> -73696.645
A11: Total coûts variables | B11: =B6+B7+B8+B9+B10 -> -418713.54 | C11: =C6+C7+C8+C9+C10 -> -295532.03 | D11: =D6+D7+D8+D9+D10 -> -301242.19 | E11: =E6+E7+E8+E9+E10 -> -307060.89 | F11: =F6+F7+F8+F9+F10 -> -312990.73 | G11: =G6+G7+G8+G9+G10 -> -319034.37 | H11: =H6+H7+H8+H9+H10 -> -325194.55 | I11: =I6+I7+I8+I9+I10 -> -331474.06 | ... AK11: =AK6+AK7+AK8+AK9+AK10 -> -669043.47
A12: MARGE DE CONTRIBUTION | B12: =B5+B11 -> 975986.46 | C12: =C5+C11 -> 1159856.4 | D12: =D5+D11 -> 1217215 | E12: =E5+E11 -> 1276972.9 | F12: =F5+F11 -> 1339261.3 | G12: =G5+G11 -> 1404217.1 | H12: =H5+H11 -> 1531107.5 | I12: =I5+I11 -> 1603018.2 | ... AK12: =AK5+AK11 -> 5682599.8
A13: % contribution | B13: =IF(B5=0,0,B12/B5) -> 0.69978236 | C13: =IF(C5=0,0,C12/C5) -> 0.79693941 | D13: =IF(D5=0,0,D12/D5) -> 0.80161298 | E13: =IF(E5=0,0,E12/E5) -> 0.80615257 | F13: =IF(F5=0,0,F12/F5) -> 0.8105672 | G13: =IF(G5=0,0,G12/G5) -> 0.81486488 | H13: =IF(H5=0,0,H12/H5) -> 0.82481593 | I13: =IF(I5=0,0,I12/I5) -> 0.82865062 | ... AK13: =IF(AK5=0,0,AK12/AK5) -> 0.89466608
A15: Publicité (budget saisi par année, Parametres section 9) | B15: =-'Plan ventes'!B6 -> -400000 | C15: =-'Plan ventes'!C6 -> -400000 | D15: =-'Plan ventes'!D6 -> -400000 | E15: =-'Plan ventes'!E6 -> -400000 | F15: =-'Plan ventes'!F6 -> -400000 | G15: =-'Plan ventes'!G6 -> -400000 | H15: =-'Plan ventes'!H6 -> -400000 | I15: =-'Plan ventes'!I6 -> -400000 | ... AK15: =-'Plan ventes'!AK6 -> -600000
A16: Contribution après pub | B16: =B12+B15 -> 575986.46 | C16: =C12+C15 -> 759856.4 | D16: =D12+D15 -> 817214.96 | E16: =E12+E15 -> 876972.94 | F16: =F12+F15 -> 939261.28 | G16: =G12+G15 -> 1004217.1 | H16: =H12+H15 -> 1131107.5 | I16: =I12+I15 -> 1203018.2 | ... AK16: =AK12+AK15 -> 5082599.8
A18: OPEX fixes (loyer, salaires chargés, hébergement, storage, modération, accompagnement) | B18: ='P&L'!B17-B15 -> -2405583 | C18: ='P&L'!C17-C15 -> -2405583 | D18: ='P&L'!D17-D15 -> -2405583 | E18: ='P&L'!E17-E15 -> -2405583 | F18: ='P&L'!F17-F15 -> -2405583 | G18: ='P&L'!G17-G15 -> -2405583 | H18: ='P&L'!H17-H15 -> -2405583 | I18: ='P&L'!I17-I15 -> -2405583 | ... AK18: ='P&L'!AK17-AK15 -> -3356412.8
A19: EBITDA (contrôle = P&L) | B19: =B16+B18 -> -1829596.5 | C19: =C16+C18 -> -1645726.6 | D19: =D16+D18 -> -1588368 | E19: =E16+E18 -> -1528610.1 | F19: =F16+F18 -> -1466321.7 | G19: =G16+G18 -> -1401365.9 | H19: =H16+H18 -> -1274475.5 | I19: =I16+I18 -> -1202564.8 | ... AK19: =AK16+AK18 -> 1726187
A20: Écart vs P&L EBITDA (doit = 0) | B20: =B19-'P&L'!B18 -> 0 | C20: =C19-'P&L'!C18 -> 0 | D20: =D19-'P&L'!D18 -> 0 | E20: =E19-'P&L'!E18 -> 0 | F20: =F19-'P&L'!F18 -> 0 | G20: =G19-'P&L'!G18 -> 0 | H20: =H19-'P&L'!H18 -> 0 | I20: =I19-'P&L'!I18 -> 0 | ... AK20: =AK19-'P&L'!AK18 -> 0
A22: Lecture : les coûts variables suivent le volume (transactions réalisées, nouveaux clients, GMV). Les OPEX fixes ne bougent qu'avec l'inflation, le scénario, le stress test et l'embauche du collab 2. Taux unitaires : Parametres section 12 ; budget pub : section 9.

Sheet P&L
A1: COMPTE DE RÉSULTAT — cascade de contribution (MGA) — M1–M36
A2: Année | B2: ='Plan ventes'!B2 -> 1 | C2: ='Plan ventes'!C2 -> 1 | D2: ='Plan ventes'!D2 -> 1 | E2: ='Plan ventes'!E2 -> 1 | F2: ='Plan ventes'!F2 -> 1 | G2: ='Plan ventes'!G2 -> 1 | H2: ='Plan ventes'!H2 -> 1 | I2: ='Plan ventes'!I2 -> 1 | ... AK2: ='Plan ventes'!AK2 -> 3
A3: Mois | B3: ='Plan ventes'!B3 -> 1 | C3: ='Plan ventes'!C3 -> 2 | D3: ='Plan ventes'!D3 -> 3 | E3: ='Plan ventes'!E3 -> 4 | F3: ='Plan ventes'!F3 -> 5 | G3: ='Plan ventes'!G3 -> 6 | H3: ='Plan ventes'!H3 -> 7 | I3: ='Plan ventes'!I3 -> 8 | ... AK3: ='Plan ventes'!AK3 -> 36
A5: Chiffre d'affaires (commissions + abonnements) | B5: ='Plan ventes'!B63-IF(Parametres!$B$158=1,Parametres!$B$164*'Plan ventes'!B60,0) -> 1394700 | C5: ='Plan ventes'!C63-IF(Parametres!$B$158=1,Parametres!$B$164*'Plan ventes'!C60,0) -> 1455388.4 | D5: ='Plan ventes'!D63-IF(Parametres!$B$158=1,Parametres!$B$164*'Plan ventes'!D60,0) -> 1518457.2 | E5: ='Plan ventes'!E63-IF(Parametres!$B$158=1,Parametres!$B$164*'Plan ventes'!E60,0) -> 1584033.8 | F5: ='Plan ventes'!F63-IF(Parametres!$B$158=1,Parametres!$B$164*'Plan ventes'!F60,0) -> 1652252 | G5: ='Plan ventes'!G63-IF(Parametres!$B$158=1,Parametres!$B$164*'Plan ventes'!G60,0) -> 1723251.5 | H5: ='Plan ventes'!H63-IF(Parametres!$B$158=1,Parametres!$B$164*'Plan ventes'!H60,0) -> 1856302 | I5: ='Plan ventes'!I63-IF(Parametres!$B$158=1,Parametres!$B$164*'Plan ventes'!I60,0) -> 1934492.3 | ... AK5: ='Plan ventes'!AK63-IF(Parametres!$B$158=1,Parametres!$B$164*'Plan ventes'!AK60,0) -> 6351643.2
A6: dont revenus récurrents (MRR) | B6: ='Plan ventes'!B61 -> 1020000 | C6: ='Plan ventes'!C61 -> 1073400 | D6: ='Plan ventes'!D61 -> 1129038 | E6: ='Plan ventes'!E61 -> 1187038.9 | F6: ='Plan ventes'!F61 -> 1247533.3 | G6: ='Plan ventes'!G61 -> 1310658.2 | H6: ='Plan ventes'!H61 -> 1376556.9 | I6: ='Plan ventes'!I61 -> 1445379.5 | ... AK6: ='Plan ventes'!AK61 -> 5294358.1
A7: Coûts variables (Mobile Money + SMS + support + vérification + litiges) | B7: =-(('Plan ventes'!B17+'Plan ventes'!B23+'Plan ventes'!B43+'Plan ventes'!B56)*Parametres!$D$105+('Plan ventes'!B19+'Plan ventes'!B52)*Parametres!$D$104*(1+Parametres!$D$46)^(B$2-1)+('Plan ventes'!B64)*Parametres!$D$106+'Plan ventes'!B66*Parametres!$D$107+'Plan ventes'!B60*Parametres!$D$108) -> -418713.54 | C7: =-(('Plan ventes'!C17+'Plan ventes'!C23+'Plan ventes'!C43+'Plan ventes'!C56)*Parametres!$D$105+('Plan ventes'!C19+'Plan ventes'!C52)*Parametres!$D$104*(1+Parametres!$D$46)^(C$2-1)+('Plan ventes'!C64)*Parametres!$D$106+'Plan ventes'!C66*Parametres!$D$107+'Plan ventes'!C60*Parametres!$D$108) -> -295532.03 | D7: =-(('Plan ventes'!D17+'Plan ventes'!D23+'Plan ventes'!D43+'Plan ventes'!D56)*Parametres!$D$105+('Plan ventes'!D19+'Plan ventes'!D52)*Parametres!$D$104*(1+Parametres!$D$46)^(D$2-1)+('Plan ventes'!D64)*Parametres!$D$106+'Plan ventes'!D66*Parametres!$D$107+'Plan ventes'!D60*Parametres!$D$108) -> -301242.19 | E7: =-(('Plan ventes'!E17+'Plan ventes'!E23+'Plan ventes'!E43+'Plan ventes'!E56)*Parametres!$D$105+('Plan ventes'!E19+'Plan ventes'!E52)*Parametres!$D$104*(1+Parametres!$D$46)^(E$2-1)+('Plan ventes'!E64)*Parametres!$D$106+'Plan ventes'!E66*Parametres!$D$107+'Plan ventes'!E60*Parametres!$D$108) -> -307060.89 | F7: =-(('Plan ventes'!F17+'Plan ventes'!F23+'Plan ventes'!F43+'Plan ventes'!F56)*Parametres!$D$105+('Plan ventes'!F19+'Plan ventes'!F52)*Parametres!$D$104*(1+Parametres!$D$46)^(F$2-1)+('Plan ventes'!F64)*Parametres!$D$106+'Plan ventes'!F66*Parametres!$D$107+'Plan ventes'!F60*Parametres!$D$108) -> -312990.73 | G7: =-(('Plan ventes'!G17+'Plan ventes'!G23+'Plan ventes'!G43+'Plan ventes'!G56)*Parametres!$D$105+('Plan ventes'!G19+'Plan ventes'!G52)*Parametres!$D$104*(1+Parametres!$D$46)^(G$2-1)+('Plan ventes'!G64)*Parametres!$D$106+'Plan ventes'!G66*Parametres!$D$107+'Plan ventes'!G60*Parametres!$D$108) -> -319034.37 | H7: =-(('Plan ventes'!H17+'Plan ventes'!H23+'Plan ventes'!H43+'Plan ventes'!H56)*Parametres!$D$105+('Plan ventes'!H19+'Plan ventes'!H52)*Parametres!$D$104*(1+Parametres!$D$46)^(H$2-1)+('Plan ventes'!H64)*Parametres!$D$106+'Plan ventes'!H66*Parametres!$D$107+'Plan ventes'!H60*Parametres!$D$108) -> -325194.55 | I7: =-(('Plan ventes'!I17+'Plan ventes'!I23+'Plan ventes'!I43+'Plan ventes'!I56)*Parametres!$D$105+('Plan ventes'!I19+'Plan ventes'!I52)*Parametres!$D$104*(1+Parametres!$D$46)^(I$2-1)+('Plan ventes'!I64)*Parametres!$D$106+'Plan ventes'!I66*Parametres!$D$107+'Plan ventes'!I60*Parametres!$D$108) -> -331474.06 | ... AK7: =-(('Plan ventes'!AK17+'Plan ventes'!AK23+'Plan ventes'!AK43+'Plan ventes'!AK56)*Parametres!$D$105+('Plan ventes'!AK19+'Plan ventes'!AK52)*Parametres!$D$104*(1+Parametres!$D$46)^(AK$2-1)+('Plan ventes'!AK64)*Parametres!$D$106+'Plan ventes'!AK66*Parametres!$D$107+'Plan ventes'!AK60*Parametres!$D$108) -> -669043.47
A8: MARGE DE CONTRIBUTION (CA + coûts variables) | B8: =B5+B7 -> 975986.46 | C8: =C5+C7 -> 1159856.4 | D8: =D5+D7 -> 1217215 | E8: =E5+E7 -> 1276972.9 | F8: =F5+F7 -> 1339261.3 | G8: =G5+G7 -> 1404217.1 | H8: =H5+H7 -> 1531107.5 | I8: =I5+I7 -> 1603018.2 | ... AK8: =AK5+AK7 -> 5682599.8
A9: % marge brute | B9: =IF(B5=0,0,B8/B5) -> 0.69978236 | C9: =IF(C5=0,0,C8/C5) -> 0.79693941 | D9: =IF(D5=0,0,D8/D5) -> 0.80161298 | E9: =IF(E5=0,0,E8/E5) -> 0.80615257 | F9: =IF(F5=0,0,F8/F5) -> 0.8105672 | G9: =IF(G5=0,0,G8/G5) -> 0.81486488 | H9: =IF(H5=0,0,H8/H5) -> 0.82481593 | I9: =IF(I5=0,0,I8/I5) -> 0.82865062 | ... AK9: =IF(AK5=0,0,AK8/AK5) -> 0.89466608
A11: Loyer et domiciliation | B11: =-Parametres!$D$112*(1+Parametres!$D$47)^(B$2-1) -> -125000 | C11: =-Parametres!$D$112*(1+Parametres!$D$47)^(C$2-1) -> -125000 | D11: =-Parametres!$D$112*(1+Parametres!$D$47)^(D$2-1) -> -125000 | E11: =-Parametres!$D$112*(1+Parametres!$D$47)^(E$2-1) -> -125000 | F11: =-Parametres!$D$112*(1+Parametres!$D$47)^(F$2-1) -> -125000 | G11: =-Parametres!$D$112*(1+Parametres!$D$47)^(G$2-1) -> -125000 | H11: =-Parametres!$D$112*(1+Parametres!$D$47)^(H$2-1) -> -125000 | I11: =-Parametres!$D$112*(1+Parametres!$D$47)^(I$2-1) -> -125000 | ... AK11: =-Parametres!$D$112*(1+Parametres!$D$47)^(AK$2-1) -> -145800
A12: Salaires chargés — fondateur + collab 1 (+ collab 2 si actif), charges patronales incluses | B12: =-(((Parametres!$D$113+Parametres!$D$114)*(1+Parametres!$D$115))*(1+Parametres!$D$47)^(B$2-1)+IF('Plan ventes'!B70=1,Parametres!$D$125*(1+Parametres!$D$115)*(1+Parametres!$D$47)^(B$2-1),0)) -> -2124000 | C12: =-(((Parametres!$D$113+Parametres!$D$114)*(1+Parametres!$D$115))*(1+Parametres!$D$47)^(C$2-1)+IF('Plan ventes'!C70=1,Parametres!$D$125*(1+Parametres!$D$115)*(1+Parametres!$D$47)^(C$2-1),0)) -> -2124000 | D12: =-(((Parametres!$D$113+Parametres!$D$114)*(1+Parametres!$D$115))*(1+Parametres!$D$47)^(D$2-1)+IF('Plan ventes'!D70=1,Parametres!$D$125*(1+Parametres!$D$115)*(1+Parametres!$D$47)^(D$2-1),0)) -> -2124000 | E12: =-(((Parametres!$D$113+Parametres!$D$114)*(1+Parametres!$D$115))*(1+Parametres!$D$47)^(E$2-1)+IF('Plan ventes'!E70=1,Parametres!$D$125*(1+Parametres!$D$115)*(1+Parametres!$D$47)^(E$2-1),0)) -> -2124000 | F12: =-(((Parametres!$D$113+Parametres!$D$114)*(1+Parametres!$D$115))*(1+Parametres!$D$47)^(F$2-1)+IF('Plan ventes'!F70=1,Parametres!$D$125*(1+Parametres!$D$115)*(1+Parametres!$D$47)^(F$2-1),0)) -> -2124000 | G12: =-(((Parametres!$D$113+Parametres!$D$114)*(1+Parametres!$D$115))*(1+Parametres!$D$47)^(G$2-1)+IF('Plan ventes'!G70=1,Parametres!$D$125*(1+Parametres!$D$115)*(1+Parametres!$D$47)^(G$2-1),0)) -> -2124000 | H12: =-(((Parametres!$D$113+Parametres!$D$114)*(1+Parametres!$D$115))*(1+Parametres!$D$47)^(H$2-1)+IF('Plan ventes'!H70=1,Parametres!$D$125*(1+Parametres!$D$115)*(1+Parametres!$D$47)^(H$2-1),0)) -> -2124000 | I12: =-(((Parametres!$D$113+Parametres!$D$114)*(1+Parametres!$D$115))*(1+Parametres!$D$47)^(I$2-1)+IF('Plan ventes'!I70=1,Parametres!$D$125*(1+Parametres!$D$115)*(1+Parametres!$D$47)^(I$2-1),0)) -> -2124000 | ... AK12: =-(((Parametres!$D$113+Parametres!$D$114)*(1+Parametres!$D$115))*(1+Parametres!$D$47)^(AK$2-1)+IF('Plan ventes'!AK70=1,Parametres!$D$125*(1+Parametres!$D$115)*(1+Parametres!$D$47)^(AK$2-1),0)) -> -3027974.4
A13: Hébergement web | B13: =-Parametres!$D$117*(1+Parametres!$D$47)^(B$2-1) -> -16583 | C13: =-Parametres!$D$117*(1+Parametres!$D$47)^(C$2-1) -> -16583 | D13: =-Parametres!$D$117*(1+Parametres!$D$47)^(D$2-1) -> -16583 | E13: =-Parametres!$D$117*(1+Parametres!$D$47)^(E$2-1) -> -16583 | F13: =-Parametres!$D$117*(1+Parametres!$D$47)^(F$2-1) -> -16583 | G13: =-Parametres!$D$117*(1+Parametres!$D$47)^(G$2-1) -> -16583 | H13: =-Parametres!$D$117*(1+Parametres!$D$47)^(H$2-1) -> -16583 | I13: =-Parametres!$D$117*(1+Parametres!$D$47)^(I$2-1) -> -16583 | ... AK13: =-Parametres!$D$117*(1+Parametres!$D$47)^(AK$2-1) -> -19342.411
A14: Object Storage | B14: =-Parametres!$D$118*(1+Parametres!$D$47)^(B$2-1) -> -30000 | C14: =-Parametres!$D$118*(1+Parametres!$D$47)^(C$2-1) -> -30000 | D14: =-Parametres!$D$118*(1+Parametres!$D$47)^(D$2-1) -> -30000 | E14: =-Parametres!$D$118*(1+Parametres!$D$47)^(E$2-1) -> -30000 | F14: =-Parametres!$D$118*(1+Parametres!$D$47)^(F$2-1) -> -30000 | G14: =-Parametres!$D$118*(1+Parametres!$D$47)^(G$2-1) -> -30000 | H14: =-Parametres!$D$118*(1+Parametres!$D$47)^(H$2-1) -> -30000 | I14: =-Parametres!$D$118*(1+Parametres!$D$47)^(I$2-1) -> -30000 | ... AK14: =-Parametres!$D$118*(1+Parametres!$D$47)^(AK$2-1) -> -34992
A15: Modération | B15: =-Parametres!$D$119*(1+Parametres!$D$47)^(B$2-1) -> -10000 | C15: =-Parametres!$D$119*(1+Parametres!$D$47)^(C$2-1) -> -10000 | D15: =-Parametres!$D$119*(1+Parametres!$D$47)^(D$2-1) -> -10000 | E15: =-Parametres!$D$119*(1+Parametres!$D$47)^(E$2-1) -> -10000 | F15: =-Parametres!$D$119*(1+Parametres!$D$47)^(F$2-1) -> -10000 | G15: =-Parametres!$D$119*(1+Parametres!$D$47)^(G$2-1) -> -10000 | H15: =-Parametres!$D$119*(1+Parametres!$D$47)^(H$2-1) -> -10000 | I15: =-Parametres!$D$119*(1+Parametres!$D$47)^(I$2-1) -> -10000 | ... AK15: =-Parametres!$D$119*(1+Parametres!$D$47)^(AK$2-1) -> -11664
A16: Marketing (accompagnement fixe + budget publicité par année) | B16: =-(Parametres!$D$120*(1+Parametres!$D$47)^(B$2-1)+'Plan ventes'!B6) -> -500000 | C16: =-(Parametres!$D$120*(1+Parametres!$D$47)^(C$2-1)+'Plan ventes'!C6) -> -500000 | D16: =-(Parametres!$D$120*(1+Parametres!$D$47)^(D$2-1)+'Plan ventes'!D6) -> -500000 | E16: =-(Parametres!$D$120*(1+Parametres!$D$47)^(E$2-1)+'Plan ventes'!E6) -> -500000 | F16: =-(Parametres!$D$120*(1+Parametres!$D$47)^(F$2-1)+'Plan ventes'!F6) -> -500000 | G16: =-(Parametres!$D$120*(1+Parametres!$D$47)^(G$2-1)+'Plan ventes'!G6) -> -500000 | H16: =-(Parametres!$D$120*(1+Parametres!$D$47)^(H$2-1)+'Plan ventes'!H6) -> -500000 | I16: =-(Parametres!$D$120*(1+Parametres!$D$47)^(I$2-1)+'Plan ventes'!I6) -> -500000 | ... AK16: =-(Parametres!$D$120*(1+Parametres!$D$47)^(AK$2-1)+'Plan ventes'!AK6) -> -716640
A17: Total OPEX | B17: =SUM(B11:B16) -> -2805583 | C17: =SUM(C11:C16) -> -2805583 | D17: =SUM(D11:D16) -> -2805583 | E17: =SUM(E11:E16) -> -2805583 | F17: =SUM(F11:F16) -> -2805583 | G17: =SUM(G11:G16) -> -2805583 | H17: =SUM(H11:H16) -> -2805583 | I17: =SUM(I11:I16) -> -2805583 | ... AK17: =SUM(AK11:AK16) -> -3956412.8
A18: EBITDA | B18: =B8+B17 -> -1829596.5 | C18: =C8+C17 -> -1645726.6 | D18: =D8+D17 -> -1588368 | E18: =E8+E17 -> -1528610.1 | F18: =F8+F17 -> -1466321.7 | G18: =G8+G17 -> -1401365.9 | H18: =H8+H17 -> -1274475.5 | I18: =I8+I17 -> -1202564.8 | ... AK18: =AK8+AK17 -> 1726187
A19: % EBITDA | B19: =IF(B5=0,0,B18/B5) -> -1.3118209 | C19: =IF(C5=0,0,C18/C5) -> -1.1307817 | D19: =IF(D5=0,0,D18/D5) -> -1.0460407 | E19: =IF(E5=0,0,E18/E5) -> -0.965011 | F19: =IF(F5=0,0,F18/F5) -> -0.88746856 | G19: =IF(G5=0,0,G18/G5) -> -0.81321033 | H19: =IF(H5=0,0,H18/H5) -> -0.68656689 | I19: =IF(I5=0,0,I18/I5) -> -0.6216436 | ... AK19: =IF(AK5=0,0,AK18/AK5) -> 0.27177014
A20: Dotations aux amortissements | B20: =-Amortissements!$H$6 -> -81666.667 | C20: =-Amortissements!$H$6 -> -81666.667 | D20: =-Amortissements!$H$6 -> -81666.667 | E20: =-Amortissements!$H$6 -> -81666.667 | F20: =-Amortissements!$H$6 -> -81666.667 | G20: =-Amortissements!$H$6 -> -81666.667 | H20: =-Amortissements!$H$6 -> -81666.667 | I20: =-Amortissements!$H$6 -> -81666.667 | ... AK20: =-Amortissements!$H$6 -> -81666.667
A21: RÉSULTAT OPÉRATIONNEL (EBIT) | B21: =B18+B20 -> -1911263.2 | C21: =C18+C20 -> -1727393.3 | D21: =D18+D20 -> -1670034.7 | E21: =E18+E20 -> -1610276.7 | F21: =F18+F20 -> -1547988.4 | G21: =G18+G20 -> -1483032.6 | H21: =H18+H20 -> -1356142.2 | I21: =I18+I20 -> -1284231.4 | ... AK21: =AK18+AK20 -> 1644520.3
A22: Charges financières (intérêts d'emprunt) | B22: =-Financement!C32 -> -322562.31 | C22: =-Financement!D32 -> -318285.66 | D22: =-Financement!E32 -> -313976.94 | E22: =-Financement!F32 -> -309635.9 | F22: =-Financement!G32 -> -305262.31 | G22: =-Financement!H32 -> -300855.91 | H22: =-Financement!I32 -> -296416.47 | I22: =-Financement!J32 -> -291943.73 | ... AK22: =-Financement!AL32 -> -152121.67
A23: RÉSULTAT AVANT IMPÔT | B23: =B21+B22 -> -2233825.5 | C23: =C21+C22 -> -2045678.9 | D23: =D21+D22 -> -1984011.6 | E23: =E21+E22 -> -1919912.6 | F23: =F21+F22 -> -1853250.7 | G23: =G21+G22 -> -1783888.5 | H23: =H21+H22 -> -1652558.7 | I23: =I21+I22 -> -1576175.2 | ... AK23: =AK21+AK22 -> 1492398.6
A24: Impôt (IS synthétique 5 % du CA ou IR 20 %) — comptabilisé au mois 12 de chaque exercice | B24: =0 -> 0 | C24: =0 -> 0 | D24: =0 -> 0 | E24: =0 -> 0 | F24: =0 -> 0 | G24: =0 -> 0 | H24: =0 -> 0 | I24: =0 -> 0 | ... L24: =0 -> 0 | M24: =-$B$34 -> -1085331 | N24: =0 -> 0 | O24: =0 -> 0 | P24: =0 -> 0 | Q24: =0 -> 0 | R24: =0 -> 0 | S24: =0 -> 0 | T24: =0 -> 0 | U24: =0 -> 0 | ... X24: =0 -> 0 | Y24: =-$C$34 -> -1904351.2 | Z24: =0 -> 0 | AA24: =0 -> 0 | AB24: =0 -> 0 | AC24: =0 -> 0 | AD24: =0 -> 0 | AE24: =0 -> 0 | AF24: =0 -> 0 | AG24: =0 -> 0 | ... AJ24: =0 -> 0 | AK24: =-$D$34 -> -3172760.8
A25: RÉSULTAT NET | B25: =B23+B24 -> -2233825.5 | C25: =C23+C24 -> -2045678.9 | D25: =D23+D24 -> -1984011.6 | E25: =E23+E24 -> -1919912.6 | F25: =F23+F24 -> -1853250.7 | G25: =G23+G24 -> -1783888.5 | H25: =H23+H24 -> -1652558.7 | I25: =I23+I24 -> -1576175.2 | ... AK25: =AK23+AK24 -> -1680362.2
A26: % marge nette | B26: =IF(B5=0,0,B25/B5) -> -1.6016531 | C26: =IF(C5=0,0,C25/C5) -> -1.4055897 | D26: =IF(D5=0,0,D25/D5) -> -1.3065971 | E26: =IF(E5=0,0,E25/E5) -> -1.2120402 | F26: =IF(F5=0,0,F25/F5) -> -1.1216513 | G26: =IF(G5=0,0,G25/G5) -> -1.0351876 | H26: =IF(H5=0,0,H25/H5) -> -0.89024233 | I26: =IF(I5=0,0,I25/I5) -> -0.81477459 | ... AK26: =IF(AK5=0,0,AK25/AK5) -> -0.26455551
A28: RÉCAPITULATIF ANNUEL ET CALCUL DE L'IMPÔT (Madagascar, LF 2026)
B29: Année 1 | C29: Année 2 | D29: Année 3
A30: Chiffre d'affaires annuel | B30: =SUMIF($B$2:$AK$2,1,$B$5:$AK$5) -> 21706621 | C30: =SUMIF($B$2:$AK$2,2,$B$5:$AK$5) -> 38087024 | D30: =SUMIF($B$2:$AK$2,3,$B$5:$AK$5) -> 63455216
A31: EBITDA annuel | B31: =SUMIF($B$2:$AK$2,1,$B$18:$AK$18) -> -15962797 | C31: =SUMIF($B$2:$AK$2,2,$B$18:$AK$18) -> -4181951.1 | D31: =SUMIF($B$2:$AK$2,3,$B$18:$AK$18) -> 8893982.1
A32: Résultat avant impôt annuel | B32: =SUMIF($B$2:$AK$2,1,$B$23:$AK$23) -> -20524109 | C32: =SUMIF($B$2:$AK$2,2,$B$23:$AK$23) -> -8074225.9 | D32: =SUMIF($B$2:$AK$2,3,$B$23:$AK$23) -> 5733504.8
A33: Déficits antérieurs reportables (régime réel) | B33: 0 | C33: =MIN(0,B32) -> -20524109 | D33: =MIN(0,B32+C32) -> -28598335
A34: Impôt dû (IS 5 % du CA si CA < seuil, sinon IR 20 %) | B34: =IF(B30<Parametres!$D$150,Parametres!$D$151*B30,MAX(Parametres!$D$152*MAX(0,B32+B33),Parametres!$D$153+Parametres!$D$154*B30)) -> 1085331 | C34: =IF(C30<Parametres!$D$150,Parametres!$D$151*C30,MAX(Parametres!$D$152*MAX(0,C32+C33),Parametres!$D$153+Parametres!$D$154*C30)) -> 1904351.2 | D34: =IF(D30<Parametres!$D$150,Parametres!$D$151*D30,MAX(Parametres!$D$152*MAX(0,D32+D33),Parametres!$D$153+Parametres!$D$154*D30)) -> 3172760.8
A35: Résultat net annuel | B35: =B32-B34 -> -21609440 | C35: =C32-C34 -> -9978577.1 | D35: =D32-D34 -> 2560744
A37: Simplifications documentées : impôt comptabilisé et payé au mois 12 de chaque exercice ; report des déficits appliqué uniquement au régime réel (IR).

Sheet Bilan
A1: BILAN SIMPLIFIÉ — actif = passif (MGA) — M0 setup + M1–M36
A2: Année | C2: 0 | D2: =INT((D3-1)/12)+1 -> 1 | E2: =INT((E3-1)/12)+1 -> 1 | F2: =INT((F3-1)/12)+1 -> 1 | G2: =INT((G3-1)/12)+1 -> 1 | H2: =INT((H3-1)/12)+1 -> 1 | I2: =INT((I3-1)/12)+1 -> 1 | J2: =INT((J3-1)/12)+1 -> 1 | K2: =INT((K3-1)/12)+1 -> 1 | ... AM2: =INT((AM3-1)/12)+1 -> 3
A3: Mois | C3: 0 | D3: 1 | E3: 2 | F3: 3 | G3: 4 | H3: 5 | I3: 6 | J3: 7 | K3: 8 | L3: 9 | M3: 10 | N3: 11 | O3: 12 | P3: 13 | Q3: 14 | R3: 15 | S3: 16 | T3: 17 | U3: 18 | V3: 19 | W3: 20 | X3: 21 | Y3: 22 | Z3: 23 | AA3: 24 | AB3: 25 | AC3: 26 | AD3: 27 | AE3: 28 | AF3: 29 | AG3: 30 | AH3: 31 | AI3: 32 | AJ3: 33 | AK3: 34 | AL3: 35 | AM3: 36
A5: ACTIF
A6: Immobilisations brutes (CAPEX) | C6: =Financement!B4 -> 4900000 | D6: =Financement!$B$4 -> 4900000 | E6: =Financement!$B$4 -> 4900000 | F6: =Financement!$B$4 -> 4900000 | G6: =Financement!$B$4 -> 4900000 | H6: =Financement!$B$4 -> 4900000 | I6: =Financement!$B$4 -> 4900000 | J6: =Financement!$B$4 -> 4900000 | K6: =Financement!$B$4 -> 4900000 | ... AM6: =Financement!$B$4 -> 4900000
A7: Amortissements cumulés | C7: 0 | D7: =-Amortissements!$H$6*D$3 -> -81666.667 | E7: =-Amortissements!$H$6*E$3 -> -163333.33 | F7: =-Amortissements!$H$6*F$3 -> -245000 | G7: =-Amortissements!$H$6*G$3 -> -326666.67 | H7: =-Amortissements!$H$6*H$3 -> -408333.33 | I7: =-Amortissements!$H$6*I$3 -> -490000 | J7: =-Amortissements!$H$6*J$3 -> -571666.67 | K7: =-Amortissements!$H$6*K$3 -> -653333.33 | ... AM7: =-Amortissements!$H$6*AM$3 -> -2940000
A8: Immobilisations nettes (VNC) | C8: =C6+C7 -> 4900000 | D8: =D6+D7 -> 4818333.3 | E8: =E6+E7 -> 4736666.7 | F8: =F6+F7 -> 4655000 | G8: =G6+G7 -> 4573333.3 | H8: =H6+H7 -> 4491666.7 | I8: =I6+I7 -> 4410000 | J8: =J6+J7 -> 4328333.3 | ... AM8: =AM6+AM7 -> 1960000
A9: Trésorerie | C9: =Tresorerie!C25 -> 47108307 | D9: =Tresorerie!D25 -> 44385929 | E9: =Tresorerie!E25 -> 41847421 | F9: =Tresorerie!F25 -> 39366271 | G9: =Tresorerie!G25 -> 36944879 | H9: =Tresorerie!H25 -> 34585776 | I9: =Tresorerie!I25 -> 32291628 | J9: =Tresorerie!J25 -> 30124371 | ... AM9: =Tresorerie!AM25 -> -2445043.6
A10: TOTAL ACTIF | C10: =C8+C9 -> 52008307 | D10: =D8+D9 -> 49204263 | E10: =E8+E9 -> 46584088 | F10: =F8+F9 -> 44021271 | G10: =G8+G9 -> 41518213 | H10: =H8+H9 -> 39077443 | I10: =I8+I9 -> 36701628 | J10: =J8+J9 -> 34452704 | ... AM10: =AM8+AM9 -> -485043.63
A12: PASSIF ET CAPITAUX PROPRES
A13: Emprunt restant dû | C13: =Financement!B23 -> 43008307 | D13: =IF(D$3>Financement!$B$25,0,Financement!C34) -> 42438088 | E13: =IF(E$3>Financement!$B$25,0,Financement!D34) -> 41863592 | F13: =IF(F$3>Financement!$B$25,0,Financement!E34) -> 41284787 | G13: =IF(G$3>Financement!$B$25,0,Financement!F34) -> 40701641 | H13: =IF(H$3>Financement!$B$25,0,Financement!G34) -> 40114122 | I13: =IF(I$3>Financement!$B$25,0,Financement!H34) -> 39522196 | J13: =IF(J$3>Financement!$B$25,0,Financement!I34) -> 38925831 | K13: =IF(K$3>Financement!$B$25,0,Financement!J34) -> 38324993 | ... AM13: =IF(AM$3>Financement!$B$25,0,Financement!AL34) -> 19542230
A14: Capitaux propres — apport | C14: =Financement!B14 -> 9000000 | D14: =Financement!$B$14 -> 9000000 | E14: =Financement!$B$14 -> 9000000 | F14: =Financement!$B$14 -> 9000000 | G14: =Financement!$B$14 -> 9000000 | H14: =Financement!$B$14 -> 9000000 | I14: =Financement!$B$14 -> 9000000 | J14: =Financement!$B$14 -> 9000000 | K14: =Financement!$B$14 -> 9000000 | ... AM14: =Financement!$B$14 -> 9000000
A15: Capitaux propres — résultat net cumulé | C15: 0 | D15: =SUM('P&L'!B25:B25) -> -2233825.5 | E15: =SUM('P&L'!B25:C25) -> -4279504.4 | F15: =SUM('P&L'!B25:D25) -> -6263516.1 | G15: =SUM('P&L'!B25:E25) -> -8183428.7 | H15: =SUM('P&L'!B25:F25) -> -10036679 | I15: =SUM('P&L'!B25:G25) -> -11820568 | J15: =SUM('P&L'!B25:H25) -> -13473127 | K15: =SUM('P&L'!B25:I25) -> -15049302 | L15: =SUM('P&L'!B25:J25) -> -16545917 | M15: =SUM('P&L'!B25:K25) -> -17959631 | N15: =SUM('P&L'!B25:L25) -> -19286928 | O15: =SUM('P&L'!B25:M25) -> -21609440 | P15: =SUM('P&L'!B25:N25) -> -22884678 | Q15: =SUM('P&L'!B25:O25) -> -24064400 | R15: =SUM('P&L'!B25:P25) -> -25144561 | S15: =SUM('P&L'!B25:Q25) -> -26121285 | T15: =SUM('P&L'!B25:R25) -> -26990516 | U15: =SUM('P&L'!B25:S25) -> -27748015 | V15: =SUM('P&L'!B25:T25) -> -28389347 | W15: =SUM('P&L'!B25:U25) -> -28909875 | X15: =SUM('P&L'!B25:V25) -> -29304754 | Y15: =SUM('P&L'!B25:W25) -> -29568916 | Z15: =SUM('P&L'!B25:X25) -> -29697065 | AA15: =SUM('P&L'!B25:Y25) -> -31588017 | AB15: =SUM('P&L'!B25:Z25) -> -32015401 | AC15: =SUM('P&L'!B25:AA25) -> -32309106 | AD15: =SUM('P&L'!B25:AB25) -> -32446509 | AE15: =SUM('P&L'!B25:AC25) -> -32423190 | AF15: =SUM('P&L'!B25:AD25) -> -32234540 | AG15: =SUM('P&L'!B25:AE25) -> -31875751 | AH15: =SUM('P&L'!B25:AF25) -> -31341814 | AI15: =SUM('P&L'!B25:AG25) -> -30627509 | AJ15: =SUM('P&L'!B25:AH25) -> -29727401 | AK15: =SUM('P&L'!B25:AI25) -> -28635832 | AL15: =SUM('P&L'!B25:AJ25) -> -27346911 | AM15: =SUM('P&L'!B25:AK25) -> -29027273
A16: TOTAL PASSIF + CP | C16: =C13+C14+C15 -> 52008307 | D16: =D13+D14+D15 -> 49204263 | E16: =E13+E14+E15 -> 46584088 | F16: =F13+F14+F15 -> 44021271 | G16: =G13+G14+G15 -> 41518213 | H16: =H13+H14+H15 -> 39077443 | I16: =I13+I14+I15 -> 36701628 | J16: =J13+J14+J15 -> 34452704 | ... AM16: =AM13+AM14+AM15 -> -485043.63
A18: Contrôle (actif − passif, doit = 0) | C18: =C10-C16 -> 0 | D18: =D10-D16 -> 0 | E18: =E10-E16 -> 0 | F18: =F10-F16 -> 0 | G18: =G10-G16 -> 0 | H18: =H10-H16 -> 0 | I18: =I10-I16 -> 0 | J18: =J10-J16 -> 0 | ... AM18: =AM10-AM16 -> -1.1175871e-08
